Workbook

Sheet Электродвигатель
A1: Дано
A2: Окружная сила | E2: 4 | F2: кН | I2: Потребляемая мощность [кВт] | M2: =E2*E3 -> 6.4 | Q2: Передача | T2: КПД от | U2: КПД до | V2: КПД | AC2: Передача | AF2: Передаточное от/до | AH2: КПД от | AI2: КПД до | AJ2: КПД (при 0) | AK2: Наклон
A3: Скорость ленты | E3: 1.6 | F3: м/с | I3: Схема | Q3: Цилиндрическая | T3: 0.96 | U3: 0.98 | V3: =AVERAGE(T3:U3) -> 0.97 | AC3: Цилиндрическая 1 | AF3: 1.6 | AG3: 8 | AH3: =T3 -> 0.96 | AI3: =U3 -> 0.98 | AJ3: =AI3+AK3*AF3 -> 0.985 | AK3: =(AI3-AH3)/(AG3-AF3) -> 0.003125
A4: Целевой показатель | E4: Максимальный КПД | I4: Дигатель->Муфта->Редуктор->Муфта->Барабан | Q4: Коническая | T4: 0.95 | U4: 0.97 | V4: =AVERAGE(T4:U4) -> 0.96 | AC4: Коническая 1 | AF4: 1 | AG4: 6.3 | AH4: =T4 -> 0.95 | AI4: =U4 -> 0.97 | AJ4: =AI4+AK4*AF4 -> 0.97377358 | AK4: =(AI4-AH4)/(AG4-AF4) -> 0.0037735849
A5: Расчётный ресурс | E5: 10000 | F5: часов | K5: Количество | M5: КПД | Q5: Планетарная 1 | T5: 0.95 | U5: 0.97 | V5: =AVERAGE(T5:U5) -> 0.96 | AC5: Планетарная 1 | AF5: 3.15 | AG5: 8 | AH5: =T5 -> 0.95 | AI5: =U5 -> 0.97 | AJ5: =AI5+AK5*AF5 -> 0.98298969 | AK5: =(AI5-AH5)/(AG5-AF5) -> 0.0041237113
A6: Ветоятность безотказной работы | E6: 0.9 | I6: Опоры | K6: 2 | M6: 0.99 | Q6: Планетарная 2 | T6: 0.92 | U6: 0.96 | V6: =AVERAGE(T6:U6) -> 0.94 | AC6: Прямозубая 2 | AF6: 12.5 | AG6: 31.5 | AH6: =T3*T3 -> 0.9216 | AI6: =U3*U3 -> 0.9604 | AJ6: =AI6+AK6*AF6 -> 0.98592632 | AK6: =(AI6-AH6)/(AG6-AF6) -> 0.0020421053
A7: Режим нагружения | E7: 3 | I7: Муфта | K7: 2 | M7: 0.98 | Q7: Волновая | T7: 0.72 | U7: 0.82 | V7: =AVERAGE(T7:U7) -> 0.77 | AC7: Планетарная 2 | AF7: 16 | AG7: 63 | AH7: =T6 -> 0.92 | AI7: =U6 -> 0.96 | AJ7: =AI7+AK7*AF7 -> 0.97361702 | AK7: =(AI7-AH7)/(AG7-AF7) -> 0.00085106383
A8: Предельная перегрузка | E8: 2.2 | I8: Передача | K8: 0 | M8: =V11 -> 0.95 | Q8: Червячная (>30) | T8: 0.7 | U8: 0.8 | V8: =AVERAGE(T8:U8) -> 0.75 | AC8: Коническо-цилиндрический | AF8: 10 | AG8: 30 | AH8: =T4*T3 -> 0.912 | AI8: =U4*U3 -> 0.9506 | AJ8: =AI8+AK8*AF8 -> 0.9699 | AK8: =(AI8-AH8)/(AG8-AF8) -> 0.00193
A9: Требования безопасности | I9: КПД без редуктора и мотора: | M9: =M7^K7*M6^K6*M8^K8 -> 0.94128804 | Q9: Червячная (14-30) | T9: 0.75 | U9: 0.85 | V9: =AVERAGE(T9:U9) -> 0.8 | AC9: Червячная 1 | AF9: 8 | AG9: 63 | AH9: =T8 -> 0.7 | AI9: =U10 -> 0.9 | AJ9: =AI9+AK9*AF9 -> 0.92909091 | AK9: =(AI9-AH9)/(AG9-AF9) -> 0.0036363636
A10: Все подвижные части накрыты кожухами | I10: Предварительное КПД редуктора | M10: 0.97 | Q10: Червячная (8-14) | T10: 0.8 | U10: 0.9 | V10: =AVERAGE(T10:U10) -> 0.85 | AC10: Волновая | AF10: 70 | AG10: 320 | AH10: =T7 -> 0.72 | AI10: =U7 -> 0.82 | AJ10: =AI10+AK10*AF10 -> 0.848 | AK10: =(AI10-AH10)/(AG10-AF10) -> 0.0004
A11: Конструктивные требования | I11: Мощность двигателя [кВт] | M11: =M2/M10/M9 -> 7.0094784 | Q11: Ременная | T11: 0.94 | U11: 0.96 | V11: =AVERAGE(T11:U11) -> 0.95
A12: Расположение вала | E12: горизонтальное | Q12: Цепная | T12: 0.92 | U12: 0.95 | V12: =AVERAGE(T12:U12) -> 0.935 | AC12: Передачи отсортированы по возрастанию КПД
A13: Высота | E13: 400 | F13: мм | G13: +-60мм | AC13: Цифра в передаче указывает количество ступеней
A14: Ширина ленты | E14: 400 | F14: мм
A15: Объём выпуска | E15: 300 | F15: шт/год
I19: Частота поля | K19: 3000 | O19: 1500 | S19: 1000 | W19: 750
I20: Мощность [кВт] | K20: Тип | L20: Частота | M20: макс/ном | N20: КПД | O20: Тип | P20: Частота | Q20: макс/ном | R20: КПД | S20: Тип | T20: Частота | U20: макс/ном | V20: КПД | W20: Тип | X20: Частота | Y20: макс/ном | Z20: КПД
I21: 0.37 | K21: - | L21: 0 | M21: 0 | N21: 0 | O21: - | P21: 0 | Q21: 0 | R21: 0
I22: 0.55 | K22: - | L22: 0 | M22: 0 | N22: 0 | O22: 71А4 | P22: 1357 | Q22: 2.2
I23: 0.75 | K23: 71А2 | L23: 2820 | M23: 2.2 | N23: 0.75 | O23: 71B4 | P23: 1350 | Q23: 2.2
I24: 1.1 | K24: 71B2 | L24: 2805 | M24: 2.2 | N24: 0.77 | O24: 80A4 | P24: 1395 | Q24: 2.2
I25: 1.5 | K25: 80A2 | L25: 2850 | M25: 2.2 | N25: 0.785 | O25: 80B4 | P25: 1395 | Q25: 2.2
I26: 2.2 | K26: 80B2 | L26: 2850 | M26: 2.2 | N26: 0.81 | O26: 90L4 | P26: 1395 | Q26: 2.2
I27: 3 | K27: 90L2 | L27: 2850 | M27: 2.2 | O27: 100S4 | P27: 1410 | Q27: 2.2
I28: 4 | K28: 100S2 | L28: 2850 | M28: 2.2 | O28: 100L4 | P28: 1410 | Q28: 2.2
I29: 5.5 | K29: 100L2 | L29: 2850 | M29: 2.2 | N29: 0.88 | O29: 112M4 | P29: 1432 | Q29: 2.2 | R29: 0.866 | S29: 132S6 | T29: 960 | U29: 2.2 | V29: 0.85 | W29: 132M8 | X29: 712 | Y29: 2.2 | Z29: 0.83
I30: 7.5 | K30: 112M2 | L30: 2895 | M30: 2.2 | N30: 0.87 | O30: 132S4 | P30: 1440 | Q30: 2.2 | R30: 0.872 | S30: 132M6 | T30: 960 | U30: 2.2 | V30: 0.86 | W30: 160S8 | X30: 727 | Y30: 2.4 | Z30: 0.85
I31: 11 | K31: 132M2 | L31: 2910 | M31: 2.2 | N31: 0.88 | O31: 132M4 | P31: 1447 | Q31: 2.2 | R31: 0.87 | S31: 160S6 | T31: 970 | U31: 2.5 | V31: 0.868 | W31: 160M8 | X31: 727 | Y31: 2.4 | Z31: 0.87
I32: 15 | K32: 160S2 | L32: 2910 | M32: 2.7 | O32: 160S4 | P32: 1455 | Q32: 2.9
I33: 18.5 | K33: 160M2 | L33: 2910 | M33: 2.7 | O33: 160M4 | P33: 1455 | Q33: 2.9
I34: 22 | K34: 180S2 | L34: 2919 | M34: 2.7 | O34: 180S4 | P34: 1462 | Q34: 2.4
I35: 30 | K35: 180M2 | L35: 2925 | M35: 2.7 | O35: 180M4 | P35: 1470 | Q35: 2.7
G36: Варианты: | I36: =_xlfn.MINIFS(I21:J35,I21:J35,">="&M11) -> 7.5 | K36: =VLOOKUP($I$36,$I$21:$R$35,3) -> 112M2 | L36: =VLOOKUP($I$36,$I$21:$R$35,4) -> 2895 | M36: =VLOOKUP($I$36,$I$21:$R$35,5) -> 2.2 | N36: =VLOOKUP($I$36,$I$21:$R$35,6) -> 0.87 | O36: =VLOOKUP($I$36,$I$21:$R$35,7) -> 132S4 | P36: =VLOOKUP($I$36,$I$21:$R$35,8) -> 1440 | Q36: =VLOOKUP($I$36,$I$21:$R$35,9) -> 2.2 | R36: =VLOOKUP($I$36,$I$21:$R$35,10) -> 0.872 | S36: =VLOOKUP($I$36,$I$21:$Z$35,11) -> 132M6 | T36: =VLOOKUP($I$36,$I$21:$Z$35,12) -> 960 | U36: =VLOOKUP($I$36,$I$21:$Z$35,13) -> 2.2 | V36: =VLOOKUP($I$36,$I$21:$Z$35,14) -> 0.86 | W36: =VLOOKUP($I$36,$I$21:$Z$35,15) -> 160S8 | X36: =VLOOKUP($I$36,$I$21:$Z$35,16) -> 727 | Y36: =VLOOKUP($I$36,$I$21:$Z$35,17) -> 2.4 | Z36: =VLOOKUP($I$36,$I$21:$Z$35,18) -> 0.85
G38: ГОСТ 22647 (ленточный транспортёр)
G39: Параметры барабана | N39: =N36*$M$9 -> 0.81892059 | R39: =R36*$M$9 -> 0.82080317 | V39: =V36*$M$9 -> 0.80950771 | Z39: =Z36*$M$9 -> 0.80009483
G40: Диаметр | I40: Частота [1/мин] | K40: Отношение | L40: Тип | N40: КПД | O40: Отношение | P40: Тип | R40: КПД | S40: Отношение | T40: Тип | V40: КПД | W40: Отношение | X40: Тип | Z40: КПД
G41: 160 | I41: =$E$3*60000/PI()/G41 -> 190.98593 | K41: =IF($I41,L$36/$I41,"-") -> 15.158185 | L41: =AC6 -> Прямозубая 2 | M41: =IF(K41<>"-",SUMIF($AC:$AE,L41,$AJ:$AJ)-K41*SUMIF($AC:$AE,L41,$AK:$AK),0) -> 0.95497171 | N41: =M41*N$39 -> 0.782046 | O41: =IF($I41,P$36/$I41,"-") -> 7.5398224 | P41: =AC3 -> Цилиндрическая 1 | Q41: =IF(O41<>"-",SUMIF($AC:$AE,P41,$AJ:$AJ)-O41*SUMIF($AC:$AE,P41,$AK:$AK),0) -> 0.96143806 | R41: =Q41*R$39 -> 0.7891514 | S41: =IF($I41,T$36/$I41,"-") -> 5.0265482 | T41: =AC3 -> Цилиндрическая 1 | U41: =IF(S41<>"-",SUMIF($AC:$AE,T41,$AJ:$AJ)-S41*SUMIF($AC:$AE,T41,$AK:$AK),0) -> 0.96929204 | V41: =U41*V$39 -> 0.78464938 | W41: =IF($I41,X$36/$I41,"-") -> 3.8065631 | X41: =AC3 -> Цилиндрическая 1 | Y41: =IF(W41<>"-",SUMIF($AC:$AE,X41,$AJ:$AJ)-W41*SUMIF($AC:$AE,X41,$AK:$AK),0) -> 0.97310449 | Z41: =Y41*Z$39 -> 0.77857588
G42: 200 | I42: =$E$3*60000/PI()/G42 -> 152.78875 | K42: =IF($I42,L$36/$I42,"-") -> 18.947731 | L42: =AC6 -> Прямозубая 2 | M42: =IF(K42<>"-",SUMIF($AC:$AE,L42,$AJ:$AJ)-K42*SUMIF($AC:$AE,L42,$AK:$AK),0) -> 0.94723306 | N42: =M42*N$39 -> 0.77570866 | O42: =IF($I42,P$36/$I42,"-") -> 9.424778 | Q42: =IF(O42<>"-",SUMIF($AC:$AE,P42,$AJ:$AJ)-O42*SUMIF($AC:$AE,P42,$AK:$AK),0) -> 0 | R42: =Q42*R$39 -> 0 | S42: =IF($I42,T$36/$I42,"-") -> 6.2831853 | T42: =AC3 -> Цилиндрическая 1 | U42: =IF(S42<>"-",SUMIF($AC:$AE,T42,$AJ:$AJ)-S42*SUMIF($AC:$AE,T42,$AK:$AK),0) -> 0.96536505 | V42: =U42*V$39 -> 0.78147045 | W42: =IF($I42,X$36/$I42,"-") -> 4.7582039 | X42: =AC3 -> Цилиндрическая 1 | Y42: =IF(W42<>"-",SUMIF($AC:$AE,X42,$AJ:$AJ)-W42*SUMIF($AC:$AE,X42,$AK:$AK),0) -> 0.97013061 | Z42: =Y42*Z$39 -> 0.77619649
G43: 250 | I43: =$E$3*60000/PI()/G43 -> 122.231 | K43: =IF($I43,L$36/$I43,"-") -> 23.684663 | L43: =AC6 -> Прямозубая 2 | M43: =IF(K43<>"-",SUMIF($AC:$AE,L43,$AJ:$AJ)-K43*SUMIF($AC:$AE,L43,$AK:$AK),0) -> 0.93755974 | N43: =M43*N$39 -> 0.76778698 | O43: =IF($I43,P$36/$I43,"-") -> 11.780972 | Q43: =IF(O43<>"-",SUMIF($AC:$AE,P43,$AJ:$AJ)-O43*SUMIF($AC:$AE,P43,$AK:$AK),0) -> 0 | R43: =Q43*R$39 -> 0 | S43: =IF($I43,T$36/$I43,"-") -> 7.8539816 | T43: =AC3 -> Цилиндрическая 1 | U43: =IF(S43<>"-",SUMIF($AC:$AE,T43,$AJ:$AJ)-S43*SUMIF($AC:$AE,T43,$AK:$AK),0) -> 0.96045631 | V43: =U43*V$39 -> 0.77749679 | W43: =IF($I43,X$36/$I43,"-") -> 5.9477548 | X43: =AC3 -> Цилиндрическая 1 | Y43: =IF(W43<>"-",SUMIF($AC:$AE,X43,$AJ:$AJ)-W43*SUMIF($AC:$AE,X43,$AK:$AK),0) -> 0.96641327 | Z43: =Y43*Z$39 -> 0.77322226
G44: 315 | I44: =$E$3*60000/PI()/G44 -> 97.008727 | K44: =IF($I44,L$36/$I44,"-") -> 29.842676 | L44: =AC6 -> Прямозубая 2 | M44: =IF(K44<>"-",SUMIF($AC:$AE,L44,$AJ:$AJ)-K44*SUMIF($AC:$AE,L44,$AK:$AK),0) -> 0.92498443 | N44: =M44*N$39 -> 0.7574888 | O44: =IF($I44,P$36/$I44,"-") -> 14.844025 | Q44: =IF(O44<>"-",SUMIF($AC:$AE,P44,$AJ:$AJ)-O44*SUMIF($AC:$AE,P44,$AK:$AK),0) -> 0 | R44: =Q44*R$39 -> 0 | S44: =IF($I44,T$36/$I44,"-") -> 9.8960169 | U44: =IF(S44<>"-",SUMIF($AC:$AE,T44,$AJ:$AJ)-S44*SUMIF($AC:$AE,T44,$AK:$AK),0) -> 0 | V44: =U44*V$39 -> 0 | W44: =IF($I44,X$36/$I44,"-") -> 7.4941711 | Y44: =IF(W44<>"-",SUMIF($AC:$AE,X44,$AJ:$AJ)-W44*SUMIF($AC:$AE,X44,$AK:$AK),0) -> 0 | Z44: =Y44*Z$39 -> 0
...

Sheet Передача
A1: Параметры передачи
A2: Тип передачи | E2: =Электродвигатель!F48 -> Цилиндрическая 1 | K2: Прямозубый вариант
A3: Передаточное отношение | E3: =Электродвигатель!F49 -> 7.5398224 | K3: Вариант | L3: HRC шестерни | M3: HRC колеса | N3: Коэф. Ширины | O3: Межосевое расстояние мм | P3: Диаметр впадин шестерни мм | Q3: Масса механизма | R3: Подходит
A4: Частота барабана | E4: =Электродвигатель!F52 -> 190.98593 | F4: 1/мин | K4: 1 | L4: 28.5 | M4: 24.8 | N4: 0.1 | O4: 280 | P4: 56.4 | Q4: 78.9 | R4: =IF(P4>$E$15,1,0) -> 1
A5: Момент барабана | E5: =Электродвигатель!F54 -> 320 | F5: Н*м | K5: 2 | L5: 28.5 | M5: 24.8 | N5: 0.15 | O5: 250 | P5: 52.85 | Q5: 74.9 | R5: =IF(P5>$E$15,1,0) -> 1
A6: Перегрузка максимальная | E6: =Электродвигатель!F58 -> 2.2 | K6: 3 | L6: 28.5 | M6: 24.8 | N6: 0.315 | O6: 200 | P6: 42.3 | Q6: 68.9 | R6: =IF(P6>$E$15,1,0) -> 1
A7: Ресурс | E7: =Электродвигатель!E5 -> 10000 | F7: часов | K7: 4 | L7: 28.5 | M7: 24.8 | N7: 0.4 | O7: 190 | P7: 38.75 | Q7: 70.8 | R7: =IF(P7>$E$15,1,0) -> 1
A8: Параметры производства | K8: 5 | L8: 49 | M8: 28.5 | N8: 0.1 | O8: 250 | P8: 52.85 | Q8: 64.6 | R8: =IF(P8>$E$15,1,0) -> 1
A9: Объём партии | E9: =Электродвигатель!E15 -> 300 | F9: шт/год | K9: 6 | L9: 49 | M9: 28.5 | N9: 0.15 | O9: 240 | P9: 49.35 | Q9: 69.4 | R9: =IF(P9>$E$15,1,0) -> 1
A10: Режим нагружения | E10: =Электродвигатель!E7 -> 3 | F10: Нормальный | K10: 7 | L10: 49 | M10: 28.5 | N10: 0.315 | O10: 180 | P10: 37.75 | Q10: 57.3 | R10: =IF(P10>$E$15,1,0) -> 1
A11: Квалитет шестерни | E11: ? | F11: 6/7/8/9 | K11: 8 | L11: 49 | M11: 28.5 | N11: 0.4 | O11: 180 | P11: 36.3 | Q11: 64.2 | R11: =IF(P11>$E$15,1,0) -> 1
A12: Вариант передачи | E12: ? | F12: Прямозубая/коническая/шевронная | K12: 9 | L12: 59 | M12: 59 | N12: 0.1 | O12: 160 | P12: 32.75 | Q12: 34.4 | R12: =IF(P12>$E$15,1,0) -> 1
A13: Параметры валов | K13: 10 | L13: 59 | M13: 59 | N13: 0.15 | O13: 140 | P13: 28.75 | Q13: 31.8 | R13: =IF(P13>$E$15,1,0) -> 0
A14: Диаметр электродвигателя | E14: =Электродвигатель!T52 -> 38 | F14: мм | K14: 11 | L14: 59 | M14: 59 | N14: 0.315 | O14: 120 | P14: 24.2 | Q14: 31.9 | R14: =IF(P14>$E$15,1,0) -> 0
A15: Диаметр быстроходного | E15: =Электродвигатель!V53 -> 32 | F15: мм | K15: 12 | L15: 59 | M15: 59 | N15: 0.4 | O15: 130 | P15: 26.25 | Q15: 38.1 | R15: =IF(P15>$E$15,1,0) -> 0
A16: Диаметр тихоходного | E16: =Электродвигатель!V55 -> 50 | F16: мм
A19: Вопросы:
A20: Как определить квалитет от массовости производтсва? | M20: Вариант | Q20: 7 | T20: Вариант | X20: 8
M21: Масса механизма | Q21: 57 | R21: кг | T21: Масса механизма | X21: 64 | Y21: кг
M22: Масса колеса | Q22: 20 | R22: кг | T22: Масса колеса | X22: 25.3 | Y22: кг
M23: Межосевое расстояние | Q23: 180 | R23: мм | T23: Межосевое расстояние | X23: 180 | Y23: мм
M24: Модуль | Q24: 2.5 | R24: мм | T24: Модуль | X24: 3 | Y24: мм
M25: Окружная сила | Q25: 2016 | R25: Н | T25: Окружная сила | X25: 2013 | Y25: Н
M26: Радиальная сила | Q26: 734 | R26: Н | T26: Радиальная сила | X26: 733 | Y26: Н
M27: Осевая сила | Q27: 0 | R27: Н | T27: Осевая сила | X27: 0 | Y27: Н
M29: Параметр | O29: Шестрерня | Q29: Колесо | T29: Параметр | V29: Шестрерня | X29: Колесо
M30: Число зубьев | O30: 17 | Q30: 127 | T30: Число зубьев | V30: 14 | X30: 106
M31: Смещение | O31: -0.3 | Q31: 0.3 | T31: Смещение | V31: 0.3 | X31: -0.3
M32: Твёрдость | O32: 49 | Q32: 28.5 | T32: Твёрдость | V32: 49 | X32: 28.5
M33: Обработка | O33: ТВЧ | Q33: Улучшение | T33: Обработка | V33: ТВЧ | X33: Улучшение
M34: Диаметры [мм] | T34: Диаметры [мм]
M35: Делительный | O35: 42.5 | Q35: 317.5 | T35: Делительный | V35: 42 | X35: 318
M36: Вершин | O36: 49 | Q36: 321 | T36: Вершин | V36: 49.8 | X36: 322
M37: Впадин | O37: 37.75 | Q37: 309.75 | T37: Впадин | V37: 36.6 | X37: 308.7
M38: Ширина | O38: 62 | Q38: 57 | T38: Ширина | V38: 79 | X38: 72
M40: Налазит на вал | O40: =O37>$E$15 -> TRUE | Q40: =Q37>$E$16 -> TRUE | V40: =V37>$E$15 -> TRUE | X40: =X37>$E$16 -> TRUE

Sheet Вал

Sheet Корпус
D4: Страницы в pdf | F4: Страницы в атласе
B5: Редуктор:
B6: Колесо | D6: 238-239 | F6: 193-194
